Workbook

Sheet FrontDesk_Log
A1: Date | B1: # | C1: Room # | D1: Full Name | E1: Amount | F1: Number of Night(s) | G1: Subtotal | H1: Total With Tax | I1: Payment Type | J1: Duration | K1: CheckIn | L1: CheckInTime | M1: CheckOut | N1: CheckOutTime | O1: HK Status | P1: HK Done | Q1: CleanedTime | R1: Desk Notes | S1: HK Notes | T1: TempNote | U1: Tax Rate | W1: Guest Email | X1: Payment Processor | Y1: Processor Receipt # | Z1: Card Last4 | AA1: Auth Code | AB1: Invoice # | AC1: Invoice Status | AD1: Invoice PDF URL | AE1: Refund Requested | AF1: Refund Amount | AG1: Refund Reason | AH1: Manager Approved | AI1: Manager Approved Time | AJ1: Manager Notes | AK1: Refund PDF URL
A2: 46021 | C2: 111 | D2: Micheal Buttler | E2: 87.61 | F2: 3 | G2: 262.83 | H2: 297 | I2: Card | K2: Yes | L2: 46021 | M2: Yes | N2: 46024.243 | O2: Cleaned - ReadyFor Rent | P2: Yes | Q2: 46024.765 | R2: Extended 1/01/2026 | AB2: INV-000007 | AC2: PAID | AD2: https://drive.google.com/file/d/1Vk1h89RRN6ImQda7PoVW7bCj7lCtUWDD/view?usp=drivesdk
A3: 46022 | C3: 110 | D3: Lopez Kivin | E3: 87.61 | F3: 1 | G3: 87.61 | H3: 99 | I3: Card | K3: Yes | L3: 46021.31 | M3: Yes | N3: 46022.311 | O3: Cleaned - ReadyFor Rent | P3: Yes | AB3: INV-000001 | AC3: PAID | AD3: https://drive.google.com/file/d/1aH0-odsNYlcR2DlXc39hJLej0ZPX5D_1/view?usp=drivesdk
A4: 46022 | C4: 117 | D4: William Anton | E4: 70.8 | F4: 1 | G4: 70.8 | H4: 80 | I4: Cash | K4: Yes | L4: 46022.445 | M4: Yes | N4: 46022.639 | O4: Cleaned - ReadyFor Rent | P4: Yes | Q4: 46025.337 | AB4: INV-000003 | AC4: PAID | AD4: https://drive.google.com/file/d/1bzw232GVmZPUsd56g4JaQ9E9pg4gHpeI/view?usp=drivesdk
A5: 46022 | C5: 119 | D5: James | E5: 70.8 | F5: 2 | G5: 141.6 | H5: 160.01 | I5: Cash | K5: Yes | L5: 46022.485 | M5: Yes | N5: 46024.389 | O5: Cleaned - ReadyFor Rent | P5: Yes | Q5: 46024.765 | AB5: INV-000005 | AC5: PAID | AD5: https://drive.google.com/file/d/17EW9PfFmiGQl8xqrd4dCneIOuTTUnAi9/view?usp=drivesdk
A6: 46022 | C6: 124 | D6: David Allen | E6: 75.22 | F6: 3 | G6: 225.66 | H6: 255 | I6: Cash | K6: Yes | L6: 46022.509 | R6: Extended 1/02/2026 | AB6: INV-000006 | AC6: PAID | AD6: https://drive.google.com/file/d/1VT1RaI4DpH5LHLto-rXfrglmWqbbXy0A/view?usp=drivesdk
A7: 46022 | C7: 107 | D7: Micheal Rare | E7: 75.22 | F7: 2 | G7: 150.44 | H7: 170 | I7: Cash | K7: Yes | L7: 46022.545 | M7: Yes | N7: 46024.27 | O7: Cleaned - ReadyFor Rent | P7: Yes | Q7: 46024.765 | R7: Extended 1/01/2026 | AB7: INV-000023 | AC7: PAID | AD7: https://drive.google.com/file/d/1kVj4zPDI6PTmRr1VvONbGBfcv7kPCJWw/view?usp=drivesdk
A8: 46022 | C8: 110 | D8: Karen Norman | E8: 75.22 | F8: 2 | G8: 150.44 | H8: 170 | I8: Cash | K8: Yes | L8: 46022.608 | M8: Yes | N8: 46024.266 | O8: Cleaned - ReadyFor Rent | P8: Yes | Q8: 46024.765 | AB8: INV-000008 | AC8: PAID | AD8: https://drive.google.com/file/d/1hj3Tn0Msd3Q7r7lFk5dgBtW2AUeNt8x1/view?usp=drivesdk
A9: 46017 | C9: 120 | D9: Nathaiel Pease | E9: 56.26 | F9: 7 | G9: 393.82 | H9: 445.02 | I9: Cash | K9: Yes | L9: 46022.612 | O9: =IF(LOWER(M9)="yes",IF(LOWER(P9)="yes","Cleaned","Ready for cleaning"),"") | AB9: INV-000009 | AC9: PAID | AD9: https://drive.google.com/file/d/1-RknhEZZTX7rHang7qZy1GVYa2J1NgvS/view?usp=drivesdk
A10: 46022 | C10: 109 | D10: darwin aleman | E10: 68.14 | F10: 1 | G10: 68.14 | H10: 77 | I10: Card | K10: Yes | L10: 46022.737 | M10: Yes | N10: 46022.964 | O10: Cleaned - ReadyFor Rent | P10: Yes | Q10: 46023.597 | R10: Paid to Kaasturi LLC | AB10: INV-000011 | AC10: PAID | AD10: https://drive.google.com/file/d/1gPhl3rRJLJhKaFKGPPNVgMGDta9R7fC1/view?usp=drivesdk
A11: 46022 | C11: 116 | D11: Fredy Cruze | E11: 79.65 | F11: 1 | G11: 79.65 | H11: 90 | I11: Cash | K11: Yes | L11: 46022.904 | M11: Yes | N11: 46023.413 | O11: Cleaned - ReadyFor Rent | P11: Yes | Q11: 46023.597 | AB11: INV-000016 | AC11: PAID | AD11: https://drive.google.com/file/d/1BWpSy6gJjT3Or9DZqq5t6XxKUURF7XvP/view?usp=drivesdk
A12: 46022 | C12: 118 | D12: Walter J Villegas | E12: 68.14 | F12: 1 | G12: 68.14 | H12: 77 | I12: Card | K12: Yes | L12: 46022.952 | M12: Yes | N12: 46022.986 | O12: Cleaned - ReadyFor Rent | P12: Yes | Q12: 46023.598 | R12: Paid to Kaasturi LLC | AB12: INV-000013 | AC12: PAID | AD12: https://drive.google.com/file/d/1G3k29OUQ_E73dDGoaF5-X5oCZR3_5wGu/view?usp=drivesdk
A13: 46022 | C13: 104 | D13: LIONEL J MAJANO-UMANA | E13: 87.61 | F13: 1 | G13: 87.61 | H13: 99 | I13: Card | K13: Yes | L13: 46022.981 | M13: Yes | N13: 46023.046 | O13: Cleaned - ReadyFor Rent | P13: Yes | Q13: 46023.597 | R13: Paid to Kaasturi LLC | AB13: INV-000015 | AC13: PAID | AD13: https://drive.google.com/file/d/1L0TtXoLVA0EhdCOynkl9PFYMkSsj6Ou6/view?usp=drivesdk
A14: 46023 | C14: 141 | D14: AVIGAIL ESPINOZA | E14: 87.61 | F14: 1 | G14: 87.61 | H14: 99 | I14: Card | K14: Yes | L14: 46023.01 | M14: Yes | N14: 46023.451 | O14: Cleaned - ReadyFor Rent | P14: Yes | Q14: 46023.598 | AB14: INV-000018 | AC14: PAID | AD14: https://drive.google.com/file/d/1uZQ6Bs_z-lz_lZJhKWINYAP1ll4uUWB2/view?usp=drivesdk
A15: 46023 | C15: 135 | D15: Jimmy ( Maint . guy) | E15: 59 | F15: 3 | G15: 177 | H15: 200.01 | I15: Cash | K15: Yes | L15: 46023.507 | O15: =IF(LOWER(M15)="yes",IF(LOWER(P15)="yes","Cleaned","Ready for cleaning"),"") | AB15: INV-000019 | AC15: PAID | AD15: https://drive.google.com/file/d/1DAWiTbmzkrewxt1sfV907XlWz0KVWf8I/view?usp=drivesdk
A16: 46023 | C16: 141 | D16: Jeon Bum Skii | E16: 88.5 | F16: 1 | G16: 88.5 | H16: 100 | I16: Cash | K16: Yes | L16: 46023.663 | M16: Yes | N16: 46023.935 | O16: Cleaned - ReadyFor Rent | P16: Yes | Q16: 46024.766 | AB16: INV-000021 | AC16: PAID | AD16: https://drive.google.com/file/d/18oj6buTNiLX8BG1WQdBzv9qLvPTX7ROS/view?usp=drivesdk
A17: 46021 | C17: 145 | D17: Josh | E17: 70.21 | F17: 3 | G17: 210.62 | H17: 238 | I17: Card | O17: =IF(LOWER(M17)="yes",IF(LOWER(P17)="yes","Cleaned","Ready for cleaning"),"") | R17: Checkout but pending 3 days
A18: 46024 | C18: 109 | D18: emmanuel | E18: 87.61 | F18: 1 | G18: 87.61 | H18: 99 | I18: Card | K18: Yes | L18: 46024.172 | M18: Yes | N18: 46024.517 | O18: Cleaned - ReadyFor Rent | P18: Yes | Q18: 46024.765 | R18: paid to kaasturi llc | AB18: INV-000022 | AC18: PAID | AD18: https://drive.google.com/file/d/15EDfzN-BQ9MdwAGU-cpbv2o7Ez5Jv2Yn/view?usp=drivesdk
A19: 46024 | C19: 146 | D19: Martin Appiah | E19: 75.22 | F19: 1 | G19: 75.22 | H19: 85 | I19: Cash | K19: Yes | L19: 46024.455 | M19: No | AB19: INV-000025 | AC19: PAID | AD19: https://drive.google.com/file/d/1YkaKh5JXj6Yv3qaFFyy9YewJu7zF3uTu/view?usp=drivesdk
A20: 46024 | C20: 144 | D20: Veronica | E20: 70.8 | F20: 1 | G20: 70.8 | H20: 80 | I20: Cash | K20: Yes | L20: 46024.492 | M20: Yes | N20: 46024.766 | O20: Ready for Cleaning | R20: 2 Hours | AB20: INV-000028 | AC20: PAID | AD20: https://drive.google.com/file/d/1tBnpqcr0-rVfGGNG26rv-5Hd0480c3yu/view?usp=drivesdk
A21: 46024 | C21: 107 | D21: carlos | E21: 61.95 | F21: 1 | G21: 61.95 | H21: 70 | I21: Cash | K21: Yes | L21: 46024.667 | M21: Yes | N21: 46024.764 | O21: Ready for Cleaning | R21: 4 Hours | AB21: INV-000027 | AC21: PAID | AD21: https://drive.google.com/file/d/1s6-9TAf0MwDrhve3x05Z_99d5uCqqSzA/view?usp=drivesdk
A22: 46024 | C22: 118 | D22: victor | E22: 77.88 | F22: 1 | G22: 77.88 | H22: 88 | I22: Card | K22: Yes | L22: 46024.819 | M22: Yes | N22: 46024.866 | O22: Ready for Cleaning | R22: paid to kaasturi | AB22: INV-000029 | AC22: PAID | AD22: https://drive.google.com/file/d/1xMQVkZDtkbyye2wmxHFWmqqadYHY7Xex/view?usp=drivesdk
A23: 46024 | C23: 111 | D23: Chris | E23: 75.22 | F23: 1 | G23: 75.22 | H23: 85 | I23: Cash | K23: Yes | L23: 46024.956 | M23: Yes | N23: 46025.023 | O23: Ready for Cleaning | R23: 2 hrs | AB23: INV-000030 | AC23: PAID | AD23: https://drive.google.com/file/d/1EATp05LQguXRLji8YA7YNkxCc1aiMxg4/view?usp=drivesdk
A24: 46025 | C24: 110 | D24: william herndosez | E24: 70.8 | F24: 1 | G24: 70.8 | H24: 80 | I24: Cash | K24: Yes | L24: 46025.283 | O24: =IF(LOWER(M24)="yes",IF(LOWER(P24)="yes","Cleaned","Ready for cleaning"),"") | R24: 4 hrs | AB24: INV-000031 | AC24: PAID | AD24: https://drive.google.com/file/d/1lI3LxOlhFvkbSDKUl0mlwd0PJfWgsJGa/view?usp=drivesdk
O25: =IF(LOWER(M25)="yes",IF(LOWER(P25)="yes","Cleaned","Ready for cleaning"),"")
O27: =IF(LOWER(M27)="yes",IF(LOWER(P27)="yes","Cleaned","Ready for cleaning"),"")
O28: =IF(LOWER(M28)="yes",IF(LOWER(P28)="yes","Cleaned","Ready for cleaning"),"")
O29: =IF(LOWER(M29)="yes",IF(LOWER(P29)="yes","Cleaned","Ready for cleaning"),"")
O30: =IF(LOWER(M30)="yes",IF(LOWER(P30)="yes","Cleaned","Ready for cleaning"),"")
O31: =IF(LOWER(M31)="yes",IF(LOWER(P31)="yes","Cleaned","Ready for cleaning"),"")
O32: =IF(LOWER(M32)="yes",IF(LOWER(P32)="yes","Cleaned","Ready for cleaning"),"")
O33: =IF(LOWER(M33)="yes",IF(LOWER(P33)="yes","Cleaned","Ready for cleaning"),"")
O34: =IF(LOWER(M34)="yes",IF(LOWER(P34)="yes","Cleaned","Ready for cleaning"),"")
O35: =IF(LOWER(M35)="yes",IF(LOWER(P35)="yes","Cleaned","Ready for cleaning"),"")
O36: =IF(LOWER(M36)="yes",IF(LOWER(P36)="yes","Cleaned","Ready for cleaning"),"")
O37: =IF(LOWER(M37)="yes",IF(LOWER(P37)="yes","Cleaned","Ready for cleaning"),"")
... O199: =IF(LOWER(M199)="yes",IF(LOWER(P199)="yes","Cleaned","Ready for cleaning"),"")

Sheet HK-Sheet
A1: ROOM # | B1: Date | C1: Note | E1: ROOM # | F1: Date | G1: Note | I1: ROOM # | J1: Date | K1: Note
A2: 101 | E2: 121 | I2: 141
A3: 102 | E3: 122 | I3: 142
A4: 103 | E4: 123 | I4: 143
A5: 104 | E5: 124 | I5: 144
A6: 105 | E6: 125 | I6: 145
A7: 106 | E7: 126 | I7: 146
A8: 107 | E8: 127 | I8: 147
A9: 108 | E9: 128 | I9: 148
A10: 109 | E10: 129 | I10: 149
A11: 110 | E11: 130 | I11: 150
A12: 111 | E12: 131 | I12: 151
A13: 112 | E13: 132 | I13: 152
... A21: 120 | E21: 140 | I21: 160
A23: ROOM # | B23: Date | C23: Note | E23: ROOM # | F23: Date | G23: Note | I23: ROOM # | J23: Date | K23: Note
A24: 101 | E24: 121 | I24: 141
A25: 102 | E25: 122 | I25: 142
A26: 103 | E26: 123 | I26: 143
A27: 104 | E27: 124 | I27: 144
A28: 105 | E28: 125 | I28: 145
A29: 106 | E29: 126 | I29: 146
A30: 107 | E30: 127 | I30: 147
A31: 108 | E31: 128 | I31: 148
A32: 109 | E32: 129 | I32: 149
A33: 110 | E33: 130 | I33: 150
A34: 111 | E34: 131 | I34: 151
A35: 112 | E35: 132 | I35: 152
... A43: 120 | E43: 140 | I43: 160

Sheet Housekeeping_Board
A1: Tablet view: Filter HK Status = 'Ready for cleaning', then sort by CheckOutTime (oldest first).
A3: =FrontDesk_Log!C3 -> 110 | B3: =FrontDesk_Log!N3 -> 46022.311 | C3: =FrontDesk_Log!O3 -> Cleaned - ReadyFor Rent | D3: =IF(C3="","",IF(NOW()-B3>TIME(1,0,0),"HIGH","NORMAL")) -> HIGH | E3: =FrontDesk_Log!P3 -> Yes | F3: =FrontDesk_Log!Q3 | G3: =FrontDesk_Log!S3
A4: =FrontDesk_Log!C4 -> 117 | B4: =FrontDesk_Log!N4 -> 46022.639 | C4: =FrontDesk_Log!O4 -> Cleaned - ReadyFor Rent | D4: =IF(C4="","",IF(NOW()-B4>TIME(1,0,0),"HIGH","NORMAL")) -> HIGH | E4: =FrontDesk_Log!P4 -> Yes | F4: =FrontDesk_Log!Q4 -> 46025.337 | G4: =FrontDesk_Log!S4
A5: =FrontDesk_Log!C5 -> 119 | B5: =FrontDesk_Log!N5 -> 46024.389 | C5: =FrontDesk_Log!O5 -> Cleaned - ReadyFor Rent | D5: =IF(C5="","",IF(NOW()-B5>TIME(1,0,0),"HIGH","NORMAL")) -> HIGH | E5: =FrontDesk_Log!P5 -> Yes | F5: =FrontDesk_Log!Q5 -> 46024.765 | G5: =FrontDesk_Log!S5
A6: =FrontDesk_Log!C6 -> 124 | B6: =FrontDesk_Log!N6 | C6: =FrontDesk_Log!O6 | D6: =IF(C6="","",IF(NOW()-B6>TIME(1,0,0),"HIGH","NORMAL")) | E6: =FrontDesk_Log!P6 | F6: =FrontDesk_Log!Q6 | G6: =FrontDesk_Log!S6
A7: =FrontDesk_Log!C7 -> 107 | B7: =FrontDesk_Log!N7 -> 46024.27 | C7: =FrontDesk_Log!O7 -> Cleaned - ReadyFor Rent | D7: =IF(C7="","",IF(NOW()-B7>TIME(1,0,0),"HIGH","NORMAL")) -> HIGH | E7: =FrontDesk_Log!P7 -> Yes | F7: =FrontDesk_Log!Q7 -> 46024.765 | G7: =FrontDesk_Log!S7
A8: =FrontDesk_Log!C8 -> 110 | B8: =FrontDesk_Log!N8 -> 46024.266 | C8: =FrontDesk_Log!O8 -> Cleaned - ReadyFor Rent | D8: =IF(C8="","",IF(NOW()-B8>TIME(1,0,0),"HIGH","NORMAL")) -> HIGH | E8: =FrontDesk_Log!P8 -> Yes | F8: =FrontDesk_Log!Q8 -> 46024.765 | G8: =FrontDesk_Log!S8
A9: =FrontDesk_Log!C9 -> 120 | B9: =FrontDesk_Log!N9 | C9: =FrontDesk_Log!O9 | D9: =IF(C9="","",IF(NOW()-B9>TIME(1,0,0),"HIGH","NORMAL")) | E9: =FrontDesk_Log!P9 | F9: =FrontDesk_Log!Q9 | G9: =FrontDesk_Log!S9
A10: =FrontDesk_Log!C10 -> 109 | B10: =FrontDesk_Log!N10 -> 46022.964 | C10: =FrontDesk_Log!O10 -> Cleaned - ReadyFor Rent | D10: =IF(C10="","",IF(NOW()-B10>TIME(1,0,0),"HIGH","NORMAL")) -> HIGH | E10: =FrontDesk_Log!P10 -> Yes | F10: =FrontDesk_Log!Q10 -> 46023.597 | G10: =FrontDesk_Log!S10
A11: =FrontDesk_Log!C11 -> 116 | B11: =FrontDesk_Log!N11 -> 46023.413 | C11: =FrontDesk_Log!O11 -> Cleaned - ReadyFor Rent | D11: =IF(C11="","",IF(NOW()-B11>TIME(1,0,0),"HIGH","NORMAL")) -> HIGH | E11: =FrontDesk_Log!P11 -> Yes | F11: =FrontDesk_Log!Q11 -> 46023.597 | G11: =FrontDesk_Log!S11
A12: =FrontDesk_Log!C12 -> 118 | B12: =FrontDesk_Log!N12 -> 46022.986 | C12: =FrontDesk_Log!O12 -> Cleaned - ReadyFor Rent | D12: =IF(C12="","",IF(NOW()-B12>TIME(1,0,0),"HIGH","NORMAL")) -> HIGH | E12: =FrontDesk_Log!P12 -> Yes | F12: =FrontDesk_Log!Q12 -> 46023.598 | G12: =FrontDesk_Log!S12
A13: =FrontDesk_Log!C13 -> 104 | B13: =FrontDesk_Log!N13 -> 46023.046 | C13: =FrontDesk_Log!O13 -> Cleaned - ReadyFor Rent | D13: =IF(C13="","",IF(NOW()-B13>TIME(1,0,0),"HIGH","NORMAL")) -> HIGH | E13: =FrontDesk_Log!P13 -> Yes | F13: =FrontDesk_Log!Q13 -> 46023.597 | G13: =FrontDesk_Log!S13
A14: =FrontDesk_Log!C14 -> 141 | B14: =FrontDesk_Log!N14 -> 46023.451 | C14: =FrontDesk_Log!O14 -> Cleaned - ReadyFor Rent | D14: =IF(C14="","",IF(NOW()-B14>TIME(1,0,0),"HIGH","NORMAL")) -> HIGH | E14: =FrontDesk_Log!P14 -> Yes | F14: =FrontDesk_Log!Q14 -> 46023.598 | G14: =FrontDesk_Log!S14
... A199: =FrontDesk_Log!C199 | B199: =FrontDesk_Log!N199 | C199: =FrontDesk_Log!O199 | D199: =IF(C199="","",IF(NOW()-B199>TIME(1,0,0),"HIGH","NORMAL")) | E199: =FrontDesk_Log!P199 | F199: =FrontDesk_Log!Q199 | G199: =FrontDesk_Log!S199

Sheet Housekeeping_Print
A1: Housekeeping - Ready for Cleaning
A3: Room # | B3: CheckOutTime | C3: Priority | D3: HK Notes | E3: Cleaned?
A4: =Housekeeping_Board!A3 -> 110 | B4: =Housekeeping_Board!B3 -> 46022.311 | C4: =Housekeeping_Board!D3 -> HIGH | D4: =Housekeeping_Board!G3 | E4: =IF(Housekeeping_Board!C3="Ready for cleaning","No","")
A5: =Housekeeping_Board!A4 -> 117 | B5: =Housekeeping_Board!B4 -> 46022.639 | C5: =Housekeeping_Board!D4 -> HIGH | D5: =Housekeeping_Board!G4 | E5: =IF(Housekeeping_Board!C4="Ready for cleaning","No","")
A6: =Housekeeping_Board!A5 -> 119 | B6: =Housekeeping_Board!B5 -> 46024.389 | C6: =Housekeeping_Board!D5 -> HIGH | D6: =Housekeeping_Board!G5 | E6: =IF(Housekeeping_Board!C5="Ready for cleaning","No","")
A7: =Housekeeping_Board!A6 -> 124 | B7: =Housekeeping_Board!B6 | C7: =Housekeeping_Board!D6 | D7: =Housekeeping_Board!G6 | E7: =IF(Housekeeping_Board!C6="Ready for cleaning","No","")
A8: =Housekeeping_Board!A7 -> 107 | B8: =Housekeeping_Board!B7 -> 46024.27 | C8: =Housekeeping_Board!D7 -> HIGH | D8: =Housekeeping_Board!G7 | E8: =IF(Housekeeping_Board!C7="Ready for cleaning","No","")
A9: =Housekeeping_Board!A8 -> 110 | B9: =Housekeeping_Board!B8 -> 46024.266 | C9: =Housekeeping_Board!D8 -> HIGH | D9: =Housekeeping_Board!G8 | E9: =IF(Housekeeping_Board!C8="Ready for cleaning","No","")
A10: =Housekeeping_Board!A9 -> 120 | B10: =Housekeeping_Board!B9 | C10: =Housekeeping_Board!D9 | D10: =Housekeeping_Board!G9 | E10: =IF(Housekeeping_Board!C9="Ready for cleaning","No","")
A11: =Housekeeping_Board!A10 -> 109 | B11: =Housekeeping_Board!B10 -> 46022.964 | C11: =Housekeeping_Board!D10 -> HIGH | D11: =Housekeeping_Board!G10 | E11: =IF(Housekeeping_Board!C10="Ready for cleaning","No","")
A12: =Housekeeping_Board!A11 -> 116 | B12: =Housekeeping_Board!B11 -> 46023.413 | C12: =Housekeeping_Board!D11 -> HIGH | D12: =Housekeeping_Board!G11 | E12: =IF(Housekeeping_Board!C11="Ready for cleaning","No","")
A13: =Housekeeping_Board!A12 -> 118 | B13: =Housekeeping_Board!B12 -> 46022.986 | C13: =Housekeeping_Board!D12 -> HIGH | D13: =Housekeeping_Board!G12 | E13: =IF(Housekeeping_Board!C12="Ready for cleaning","No","")
A14: =Housekeeping_Board!A13 -> 104 | B14: =Housekeeping_Board!B13 -> 46023.046 | C14: =Housekeeping_Board!D13 -> HIGH | D14: =Housekeeping_Board!G13 | E14: =IF(Housekeeping_Board!C13="Ready for cleaning","No","")
A15: =Housekeeping_Board!A14 -> 141 | B15: =Housekeeping_Board!B14 -> 46023.451 | C15: =Housekeeping_Board!D14 -> HIGH | D15: =Housekeeping_Board!G14 | E15: =IF(Housekeeping_Board!C14="Ready for cleaning","No","")
... A100: =Housekeeping_Board!A99 | B100: =Housekeeping_Board!B99 | C100: =Housekeeping_Board!D99 | D100: =Housekeeping_Board!G99 | E100: =IF(Housekeeping_Board!C99="Ready for cleaning","No","")

Sheet Daily_Dashboard
A1: Daily Dashboard
A3: Report Date | B3: 46025
A5: Checked-in today | B5: 1
A6: Checked-out today | B6: 0
A7: Ready for cleaning (today) | B7: 0
A8: Cleaned (today) | B8: 0
A9: Cash total (today) | B9: 0
A10: Card total (today) | B10: 0
A11: Total revenue (today) | B11: 0
A13: Cash Reconciliation (Front Desk)
A15: Expected Cash (from log) | B15: 0
A16: Actual Cash Counted
A17: Over / Short | B17: =IF(B16="","",B16-B15)

Sheet Rooms_Master
A1: Room # | B1: Type | C1: Label | D1: Notes
A2: 101 | B2: Maintenance | C2: [Storage]
A3: 102 | B3: Maintenance | C3: [Supplies]
A4: 103 | C4: [FB]
A5: 104 | C5: [FB]
A6: 105 | B6: Maintenance | C6: [MgrRM]
A7: 106 | C7: [KB]
A8: 107 | C8: [KB]
A9: 108 | C9: [DB]
A10: 109 | C10: [DB]
A11: 110 | C11: [KB]
A12: 111 | C12: [KB]
A13: 112 | C13: [KB]
A14: 113 | C14: [None]
A15: 114 | B15: Out of Order | C15: [KB] - water
A16: 115 | B16: Construction | C16: [KB] - Celling
A17: 116 | C17: [DB]
A18: 117 | C18: [KB]
A19: 118 | C19: [FB]
A20: 119 | C20: [FB]
A21: 120 | C21: [KB]
A22: 121 | C22: [KB]
A23: 122 | B23: Out of Order | C23: [KB] - water
A24: 123 | B24: Out of Order | C24: [KB] - water
A25: 124 | C25: [KB]
A26: 125 | B26: Construction | C26: [KB]
A27: 126 | C27: [DB]
A28: 127 | B28: Construction | C28: [KB]
A29: 128 | B29: Construction | C29: [DB]
A30: 129 | B30: Construction | C30: [KB]
A31: 130 | B31: Construction | C31: [KB]
A32: 131 | B32: Construction
A33: 132 | B33: Construction
A34: 133 | B34: Construction
A35: 134 | B35: Construction
A36: 135 | C36: KDB
A37: 136 | C37: KDB
A38: 137 | C38: KDB
A39: 138 | B39: Construction | C39: [Storage]
A40: 139 | C40: [KB]
...

Sheet AppsScript
A1: Google Apps Script (copy/paste into Extensions → Apps Script)
A3: Includes: timestamps, HK Done -> CleanedTime, protections, nightly reset, and housekeeping PDF export.
A5: /**
A6: * Lee High Inn Motel - Invoice + Refund Approval Automation
A7: *
A8: * What it does:
A9: * - When CheckOut = Yes: stamps CheckOutTime (EST), generates PDF invoice w/ logo + IRS-style receipt wording,
A10: * saves to Drive, emails guest (if Guest Email provided).
A11: * - Supports Stripe/Square receipt numbers (Processor Receipt #).
A12: * - Refund workflow:
A13: * Refund Requested = Yes -> email manager for approval and set Invoice Status = REFUND_REQUESTED
A14: * Manager Approved = Yes -> stamp Manager Approved Time, set Invoice Status = REFUNDED, generate refund receipt PDF
... A328: }

Sheet AppScrip-bkup-01-03-26
A1: /*********************************************************
A2: * Lee High Inn – Enhanced Script (Header-Driven)
A3: * Features:
A4: * 1) F is now "Number of Night(s)" and drives Subtotal/Total
A5: * 2) Subtotal/Total auto-update when Nights/Amount/Tax Rate changes
A6: * 3) CheckIn/CheckOut timestamps reliably stamp again
A7: * 4) Repairs missing headers (U/V blank titles issue)
A8: * 5) Adds menu: Lee High Inn → Generate/Reprint Invoice
A9: * 6) Optionally hides Duration and TempNote (instead of deleting)
A10: * 7) Housekeeping automation (HK Done timestamp, color coding)
A11: * 8) Payment Type handling and validation
A12: * 9) Daily/weekly reporting functions
... A2660: }

Sheet AppScript-Backup_01032026
A1: Google Apps Script (copy/paste into Extensions → Apps Script)
A3: Includes: timestamps, HK Done -> CleanedTime, protections, nightly reset, and housekeeping PDF export.
A5: /*********************************************************
A6: * Lee High Inn – Enhanced Script (Header-Driven)
A7: * Features:
A8: * 1) F is now "Number of Night(s)" and drives Subtotal/Total
A9: * 2) Subtotal/Total auto-update when Nights/Amount/Tax Rate changes
A10: * 3) CheckIn/CheckOut timestamps reliably stamp again
A11: * 4) Repairs missing headers (U/V blank titles issue)
A12: * 5) Adds menu: Lee High Inn → Generate/Reprint Invoice
A13: * 6) Optionally hides Duration and TempNote (instead of deleting)
A14: * 7) Housekeeping automation (HK Done timestamp, color coding)
... A2081: }
